<?xml version="1.0" encoding="utf-8"?>
<!-- =================================================================================== -->
<!-- |    This document was autogenerated by xacro from darwinmod.xacro                | -->
<!-- |    EDITING THIS FILE BY HAND IS NOT RECOMMENDED                                 | -->
<!-- =================================================================================== -->
<robot name="darwinOP">
  <link name="left_foot_sensor_m0">
    <inertial>
      <origin rpy="0 0 0" xyz="0 0 0"/>
      <mass value="0.01"/>
      <inertia ixx="0.000" ixy="0.000" ixz="0.000" iyy="0.000" iyz="0.000" izz="0.000"/>
    </inertial>
    <visual>
      <origin rpy="0 0 0" xyz="0 0 0"/>
      <geometry>
        <box size="0.025 0.025 0.002"/>
      </geometry>
      <material name="">
        <color rgba="0.75294 0.75294 0.75294 1"/>
      </material>
    </visual>
    <collision>
      <origin rpy="0 0 0" xyz="0 0 0"/>
      <geometry>
        <box size="0.025 0.025 0.002"/>
      </geometry>
    </collision>
  </link>
  <joint name="left_foot_sensor_m0_j" type="revolute">
    <origin rpy="0 0 0" xyz="-0.03 -0.03 -0.034"/>
    <parent link="left_m6"/>
    <child link="left_foot_sensor_m0"/>
    <axis xyz="0 1 0"/>
    <limit effort="0" lower="-0.001" upper="0.001" velocity="0"/>
  </joint>
  <gazebo reference="left_foot_sensor_m0_j">
    <provideFeedback>true</provideFeedback>
  </gazebo>
  <gazebo>
    <plugin filename="libgazebo_ros_ft_sensor.so" name="ft_sensor">
      <always_on>true</always_on>
      <updateRate>100.0</updateRate>
      <topicName>/leap_one/left_foot_sensor_m0</topicName>
      <jointName>left_foot_sensor_m0_j</jointName>
    </plugin>
  </gazebo>
  <gazebo reference="left_foot_sensor_m0">
    <material>Gazebo/Blue</material>
    <mu1>9000</mu1>
    <mu2>9000</mu2>
    <kp>1000000.0</kp>
    <kd>10.0</kd>
    <minDepth>0.001</minDepth>
    <maxContacts>100</maxContacts>
  </gazebo>
  <link name="left_foot_sensor_m1">
    <inertial>
      <origin rpy="0 0 0" xyz="0 0 0"/>
      <mass value="0.01"/>
      <inertia ixx="0.000" ixy="0.000" ixz="0.000" iyy="0.000" iyz="0.000" izz="0.000"/>
    </inertial>
    <visual>
      <origin rpy="0 0 0" xyz="0 0 0"/>
      <geometry>
        <box size="0.025 0.025 0.002"/>
      </geometry>
      <material name="">
        <color rgba="0.75294 0.75294 0.75294 1"/>
      </material>
    </visual>
    <collision>
      <origin rpy="0 0 0" xyz="0 0 0"/>
      <geometry>
        <box size="0.025 0.025 0.002"/>
      </geometry>
    </collision>
  </link>
  <joint name="left_foot_sensor_m1_j" type="revolute">
    <origin rpy="0 0 0" xyz="0.03 -0.03 -0.034"/>
    <parent link="left_m6"/>
    <child link="left_foot_sensor_m1"/>
    <axis xyz="0 1 0"/>
    <limit effort="0" lower="-0.001" upper="0.001" velocity="0"/>
  </joint>
  <gazebo reference="left_foot_sensor_m1_j">
    <provideFeedback>true</provideFeedback>
  </gazebo>
  <gazebo>
    <plugin filename="libgazebo_ros_ft_sensor.so" name="ft_sensor">
      <always_on>true</always_on>
      <updateRate>100.0</updateRate>
      <topicName>/leap_one/left_foot_sensor_m1</topicName>
      <jointName>left_foot_sensor_m1_j</jointName>
    </plugin>
  </gazebo>
  <gazebo reference="left_foot_sensor_m1">
    <material>Gazebo/Blue</material>
    <mu1>9000</mu1>
    <mu2>9000</mu2>
    <kp>1000000.0</kp>
    <kd>10.0</kd>
    <minDepth>0.001</minDepth>
    <maxContacts>100</maxContacts>
  </gazebo>
  <link name="left_foot_sensor_m2">
    <inertial>
      <origin rpy="0 0 0" xyz="0 0 0"/>
      <mass value="0.01"/>
      <inertia ixx="0.000" ixy="0.000" ixz="0.000" iyy="0.000" iyz="0.000" izz="0.000"/>
    </inertial>
    <visual>
      <origin rpy="0 0 0" xyz="0 0 0"/>
      <geometry>
        <box size="0.025 0.025 0.002"/>
      </geometry>
      <material name="">
        <color rgba="0.75294 0.75294 0.75294 1"/>
      </material>
    </visual>
    <collision>
      <origin rpy="0 0 0" xyz="0 0 0"/>
      <geometry>
        <box size="0.025 0.025 0.002"/>
      </geometry>
    </collision>
  </link>
  <joint name="left_foot_sensor_m2_j" type="revolute">
    <origin rpy="0 0 0" xyz="-0.03 0.03 -0.034"/>
    <parent link="left_m6"/>
    <child link="left_foot_sensor_m2"/>
    <axis xyz="0 1 0"/>
    <limit effort="0" lower="-0.001" upper="0.001" velocity="0"/>
  </joint>
  <gazebo reference="left_foot_sensor_m2_j">
    <provideFeedback>true</provideFeedback>
  </gazebo>
  <gazebo>
    <plugin filename="libgazebo_ros_ft_sensor.so" name="ft_sensor">
      <always_on>true</always_on>
      <updateRate>100.0</updateRate>
      <topicName>/leap_one/left_foot_sensor_m2</topicName>
      <jointName>left_foot_sensor_m2_j</jointName>
    </plugin>
  </gazebo>
  <gazebo reference="left_foot_sensor_m2">
    <material>Gazebo/Blue</material>
    <mu1>9000</mu1>
    <mu2>9000</mu2>
    <kp>1000000.0</kp>
    <kd>10.0</kd>
    <minDepth>0.001</minDepth>
    <maxContacts>100</maxContacts>
  </gazebo>
  <link name="left_foot_sensor_m3">
    <inertial>
      <origin rpy="0 0 0" xyz="0 0 0"/>
      <mass value="0.01"/>
      <inertia ixx="0.000" ixy="0.000" ixz="0.000" iyy="0.000" iyz="0.000" izz="0.000"/>
    </inertial>
    <visual>
      <origin rpy="0 0 0" xyz="0 0 0"/>
      <geometry>
        <box size="0.025 0.025 0.002"/>
      </geometry>
      <material name="">
        <color rgba="0.75294 0.75294 0.75294 1"/>
      </material>
    </visual>
    <collision>
      <origin rpy="0 0 0" xyz="0 0 0"/>
      <geometry>
        <box size="0.025 0.025 0.002"/>
      </geometry>
    </collision>
  </link>
  <joint name="left_foot_sensor_m3_j" type="revolute">
    <origin rpy="0 0 0" xyz="0.03 0.03 -0.034"/>
    <parent link="left_m6"/>
    <child link="left_foot_sensor_m3"/>
    <axis xyz="0 1 0"/>
    <limit effort="0" lower="-0.001" upper="0.001" velocity="0"/>
  </joint>
  <gazebo reference="left_foot_sensor_m3_j">
    <provideFeedback>true</provideFeedback>
  </gazebo>
  <gazebo>
    <plugin filename="libgazebo_ros_ft_sensor.so" name="ft_sensor">
      <always_on>true</always_on>
      <updateRate>100.0</updateRate>
      <topicName>/leap_one/left_foot_sensor_m3</topicName>
      <jointName>left_foot_sensor_m3_j</jointName>
    </plugin>
  </gazebo>
  <gazebo reference="left_foot_sensor_m3">
    <material>Gazebo/Blue</material>
    <mu1>9000</mu1>
    <mu2>9000</mu2>
    <kp>1000000.0</kp>
    <kd>10.0</kd>
    <minDepth>0.001</minDepth>
    <maxContacts>100</maxContacts>
  </gazebo>
  <link name="right_foot_sensor_m0">
    <inertial>
      <origin rpy="0 0 0" xyz="0 0 0"/>
      <mass value="0.01"/>
      <inertia ixx="0.000" ixy="0.000" ixz="0.000" iyy="0.000" iyz="0.000" izz="0.000"/>
    </inertial>
    <visual>
      <origin rpy="0 0 0" xyz="0 0 0"/>
      <geometry>
        <box size="0.025 0.025 0.002"/>
      </geometry>
      <material name="">
        <color rgba="0.75294 0.75294 0.75294 1"/>
      </material>
    </visual>
    <collision>
      <origin rpy="0 0 0" xyz="0 0 0"/>
      <geometry>
        <box size="0.025 0.025 0.002"/>
      </geometry>
    </collision>
  </link>
  <joint name="right_foot_sensor_m0_j" type="revolute">
    <origin rpy="0 0 0" xyz="-0.03 -0.03 -0.034"/>
    <parent link="right_m6"/>
    <child link="right_foot_sensor_m0"/>
    <axis xyz="0 1 0"/>
    <limit effort="0" lower="-0.001" upper="0.001" velocity="0"/>
  </joint>
  <gazebo reference="right_foot_sensor_m0_j">
    <provideFeedback>true</provideFeedback>
  </gazebo>
  <gazebo>
    <plugin filename="libgazebo_ros_ft_sensor.so" name="ft_sensor">
      <always_on>true</always_on>
      <updateRate>100.0</updateRate>
      <topicName>/leap_one/right_foot_sensor_m0</topicName>
      <jointName>right_foot_sensor_m0_j</jointName>
    </plugin>
  </gazebo>
  <gazebo reference="right_foot_sensor_m0">
    <material>Gazebo/Blue</material>
    <mu1>9000</mu1>
    <mu2>9000</mu2>
    <kp>1000000.0</kp>
    <kd>10.0</kd>
    <minDepth>0.001</minDepth>
    <maxContacts>100</maxContacts>
  </gazebo>
  <link name="right_foot_sensor_m1">
    <inertial>
      <origin rpy="0 0 0" xyz="0 0 0"/>
      <mass value="0.01"/>
      <inertia ixx="0.000" ixy="0.000" ixz="0.000" iyy="0.000" iyz="0.000" izz="0.000"/>
    </inertial>
    <visual>
      <origin rpy="0 0 0" xyz="0 0 0"/>
      <geometry>
        <box size="0.025 0.025 0.002"/>
      </geometry>
      <material name="">
        <color rgba="0.75294 0.75294 0.75294 1"/>
      </material>
    </visual>
    <collision>
      <origin rpy="0 0 0" xyz="0 0 0"/>
      <geometry>
        <box size="0.025 0.025 0.002"/>
      </geometry>
    </collision>
  </link>
  <joint name="right_foot_sensor_m1_j" type="revolute">
    <origin rpy="0 0 0" xyz="0.03 -0.03 -0.034"/>
    <parent link="right_m6"/>
    <child link="right_foot_sensor_m1"/>
    <axis xyz="0 1 0"/>
    <limit effort="0" lower="-0.001" upper="0.001" velocity="0"/>
  </joint>
  <gazebo reference="right_foot_sensor_m1_j">
    <provideFeedback>true</provideFeedback>
  </gazebo>
  <gazebo>
    <plugin filename="libgazebo_ros_ft_sensor.so" name="ft_sensor">
      <always_on>true</always_on>
      <updateRate>100.0</updateRate>
      <topicName>/leap_one/right_foot_sensor_m1</topicName>
      <jointName>right_foot_sensor_m1_j</jointName>
    </plugin>
  </gazebo>
  <gazebo reference="right_foot_sensor_m1">
    <material>Gazebo/Blue</material>
    <mu1>9000</mu1>
    <mu2>9000</mu2>
    <kp>1000000.0</kp>
    <kd>10.0</kd>
    <minDepth>0.001</minDepth>
    <maxContacts>100</maxContacts>
  </gazebo>
  <link name="right_foot_sensor_m2">
    <inertial>
      <origin rpy="0 0 0" xyz="0 0 0"/>
      <mass value="0.01"/>
      <inertia ixx="0.000" ixy="0.000" ixz="0.000" iyy="0.000" iyz="0.000" izz="0.000"/>
    </inertial>
    <visual>
      <origin rpy="0 0 0" xyz="0 0 0"/>
      <geometry>
        <box size="0.025 0.025 0.002"/>
      </geometry>
      <material name="">
        <color rgba="0.75294 0.75294 0.75294 1"/>
      </material>
    </visual>
    <collision>
      <origin rpy="0 0 0" xyz="0 0 0"/>
      <geometry>
        <box size="0.025 0.025 0.002"/>
      </geometry>
    </collision>
  </link>
  <joint name="right_foot_sensor_m2_j" type="revolute">
    <origin rpy="0 0 0" xyz="-0.03 0.03 -0.034"/>
    <parent link="right_m6"/>
    <child link="right_foot_sensor_m2"/>
    <axis xyz="0 1 0"/>
    <limit effort="0" lower="-0.001" upper="0.001" velocity="0"/>
  </joint>
  <gazebo reference="right_foot_sensor_m2_j">
    <provideFeedback>true</provideFeedback>
  </gazebo>
  <gazebo>
    <plugin filename="libgazebo_ros_ft_sensor.so" name="ft_sensor">
      <always_on>true</always_on>
      <updateRate>100.0</updateRate>
      <topicName>/leap_one/right_foot_sensor_m2</topicName>
      <jointName>right_foot_sensor_m2_j</jointName>
    </plugin>
  </gazebo>
  <gazebo reference="right_foot_sensor_m2">
    <material>Gazebo/Blue</material>
    <mu1>9000</mu1>
    <mu2>9000</mu2>
    <kp>1000000.0</kp>
    <kd>10.0</kd>
    <minDepth>0.001</minDepth>
    <maxContacts>100</maxContacts>
  </gazebo>
  <link name="right_foot_sensor_m3">
    <inertial>
      <origin rpy="0 0 0" xyz="0 0 0"/>
      <mass value="0.01"/>
      <inertia ixx="0.000" ixy="0.000" ixz="0.000" iyy="0.000" iyz="0.000" izz="0.000"/>
    </inertial>
    <visual>
      <origin rpy="0 0 0" xyz="0 0 0"/>
      <geometry>
        <box size="0.025 0.025 0.002"/>
      </geometry>
      <material name="">
        <color rgba="0.75294 0.75294 0.75294 1"/>
      </material>
    </visual>
    <collision>
      <origin rpy="0 0 0" xyz="0 0 0"/>
      <geometry>
        <box size="0.025 0.025 0.002"/>
      </geometry>
    </collision>
  </link>
  <joint name="right_foot_sensor_m3_j" type="revolute">
    <origin rpy="0 0 0" xyz="0.03 0.03 -0.034"/>
    <parent link="right_m6"/>
    <child link="right_foot_sensor_m3"/>
    <axis xyz="0 1 0"/>
    <limit effort="0" lower="-0.001" upper="0.001" velocity="0"/>
  </joint>
  <gazebo reference="right_foot_sensor_m3_j">
    <provideFeedback>true</provideFeedback>
  </gazebo>
  <gazebo>
    <plugin filename="libgazebo_ros_ft_sensor.so" name="ft_sensor">
      <always_on>true</always_on>
      <updateRate>100.0</updateRate>
      <topicName>/leap_one/right_foot_sensor_m3</topicName>
      <jointName>right_foot_sensor_m3_j</jointName>
    </plugin>
  </gazebo>
  <gazebo reference="right_foot_sensor_m3">
    <material>Gazebo/Blue</material>
    <mu1>9000</mu1>
    <mu2>9000</mu2>
    <kp>1000000.0</kp>
    <kd>10.0</kd>
    <minDepth>0.001</minDepth>
    <maxContacts>100</maxContacts>
  </gazebo>
</robot>

